<?xml version="1.0"?>

<robot name="gen3_arm" xmlns:xacro="http://ros.org/wiki/xacro">

  <!-- Propagate last link name information because it is the gripper's parent link -->
  <xacro:property name="last_arm_link" value="end_effector_link"/>

  <xacro:macro name="load_arm" params="parent:='' dof vision prefix *origin">
      <link name="${prefix}base_link">
        <inertial>
          <origin xyz="-0.000648 -0.000166 0.084487" rpy="0 0 0" />
          <mass value="1.697" />
          <inertia ixx="0.004622" ixy="9E-06" ixz="6E-05" iyy="0.004495" iyz="9E-06" izz="0.002079" />
        </inertial>
        <visual>
          <origin xyz="0 0 0" rpy="0 0 0" />
          <geometry>
            <mesh filename="package://kortex_description/arms/gen3/${dof}dof/meshes/base_link.STL" />
          </geometry>
          <material name="">
            <color rgba="0.75294 0.75294 0.75294 1" />
          </material>
        </visual>
        <collision>
          <origin xyz="0 0 0" rpy="0 0 0" />
          <geometry>
            <mesh filename="package://kortex_description/arms/gen3/${dof}dof/meshes/base_link.STL" />
          </geometry>
        </collision>
    </link>
    <link name="${prefix}shoulder_link">
      <inertial>
        <origin xyz="-2.3E-05 -0.010364 -0.07336" rpy="0 0 0" />
        <!--origin xyz="-2.3E-05 -0.010364 -0.1" rpy="0 0 0" /-->
        <mass value="1.3773" />
        <inertia ixx="0.00457" ixy="1E-06" ixz="2E-06" iyy="0.004831" iyz="0.000448" izz="0.001409" />
      </inertial>
      <visual>
        <origin xyz="0 0 0" rpy="0 0 0" />
        <geometry>
          <mesh filename="package://kortex_description/arms/gen3/${dof}dof/meshes/shoulder_link.STL" />
        </geometry>
        <material name="">
          <color rgba="0.75294 0.75294 0.75294 1" />
        </material>
      </visual>
      <collision>
        <origin xyz="0 0 0" rpy="0 0 0" />
        <geometry>
          <mesh filename="package://kortex_description/arms/gen3/${dof}dof/meshes/shoulder_link.STL" />
        </geometry>
      </collision>
    </link>
    <joint
      name="${prefix}joint_1"
      type="continuous">
      <origin xyz="0 0 0.15643" rpy="3.1416 2.7629E-18 -4.9305E-36" />
      <parent
        link="${prefix}base_link" />
      <child
        link="${prefix}shoulder_link" />
      <axis
        xyz="0 0 1" />
      <limit
        effort="39"
        velocity="1.3963" />
    </joint>
    <link name="${prefix}half_arm_1_link">
      <inertial>
        <origin xyz="-4.4E-05 -0.09958 -0.013278" rpy="0 0 0" />
        <mass value="1.1636" />
        <inertia ixx="0.011088" ixy="5E-06" ixz="0" iyy="0.001072" iyz="-0.000691" izz="0.011255" />
      </inertial>
      <visual>
        <origin xyz="0 0 0" rpy="0 0 0" />
        <geometry>
          <mesh filename="package://kortex_description/arms/gen3/${dof}dof/meshes/half_arm_1_link.STL" />
        </geometry>
        <material name="">
          <color rgba="0.75294 0.75294 0.75294 1" />
        </material>
      </visual>
      <collision>
        <origin xyz="0 0 0" rpy="0 0 0" />
        <geometry>
          <mesh filename="package://kortex_description/arms/gen3/${dof}dof/meshes/half_arm_1_link.STL" />
        </geometry>
      </collision>
    </link>
    <joint
      name="${prefix}joint_2"
      type="revolute">
      <origin xyz="0 0.005375 -0.12838" rpy="1.5708 2.1343E-17 -1.1102E-16" />
      <parent
        link="${prefix}shoulder_link" />
      <child
        link="${prefix}half_arm_1_link" />
      <axis
        xyz="0 0 1" />
      <limit lower="-2.25" upper="2.25" effort="39" velocity="1.3963" />
    </joint>
    <link name="${prefix}half_arm_2_link">
      <inertial>
        <origin xyz="-4.4E-05 -0.006641 -0.117892" rpy="0 0 0" />
        <mass value="1.1636" />
        <inertia ixx="0.010932" ixy="0" ixz="-7E-06" iyy="0.011127" iyz="0.000606" izz="0.001043" />
      </inertial>
      <visual>
        <origin xyz="0 0 0" rpy="0 0 0" />
        <geometry>
          <mesh filename="package://kortex_description/arms/gen3/${dof}dof/meshes/half_arm_2_link.STL" />
        </geometry>
        <material name="">
          <color rgba="0.75294 0.75294 0.75294 1" />
        </material>
      </visual>
      <collision>
        <origin xyz="0 0 0" rpy="0 0 0" />
        <geometry>
          <mesh filename="package://kortex_description/arms/gen3/${dof}dof/meshes/half_arm_2_link.STL" />
        </geometry>
      </collision>
    </link>
    <joint
      name="${prefix}joint_3"
      type="continuous">
      <origin xyz="0 -0.21038 -0.006375" rpy="-1.5708 1.2326E-32 -2.9122E-16" />
      <parent
        link="${prefix}half_arm_1_link" />
      <child
        link="${prefix}half_arm_2_link" />
      <axis
        xyz="0 0 1" />
      <limit
        effort="39"
        velocity="1.3963" />
    </joint>
    <link name="${prefix}forearm_link">
      <inertial>
        <origin xyz="-1.8E-05 -0.075478 -0.015006" rpy="0 0 0" />
        <mass value="0.9302" />
        <inertia ixx="0.008147" ixy="-1E-06" ixz="0" iyy="0.000631" iyz="-0.0005" izz="0.008316" />
      </inertial>
      <visual>
        <origin xyz="0 0 0" rpy="0 0 0" />
        <geometry>
          <mesh filename="package://kortex_description/arms/gen3/${dof}dof/meshes/forearm_link.STL" />
        </geometry>
        <material name="">
          <color rgba="0.75294 0.75294 0.75294 1" />
        </material>
      </visual>
      <collision>
        <origin xyz="0 0 0" rpy="0 0 0" />
        <geometry>
          <mesh filename="package://kortex_description/arms/gen3/${dof}dof/meshes/forearm_link.STL" />
        </geometry>
      </collision>
    </link>
    <joint
      name="${prefix}joint_4"
      type="revolute">
      <origin xyz="0 0.006375 -0.21038" rpy="1.5708 -6.6954E-17 -1.6653E-16" />
      <parent
        link="${prefix}half_arm_2_link" />
      <child
        link="${prefix}forearm_link" />
      <axis
        xyz="0 0 1" />
      <limit lower="-2.57" upper="2.57" effort="39" velocity="1.3963" />
    </joint>
    <link name="${prefix}spherical_wrist_1_link">
      <inertial>
        <origin xyz="1E-06 -0.009432 -0.063883" rpy="0 0 0" />
        <mass value="0.6781" />
        <inertia ixx="0.001596" ixy="0" ixz="0" iyy="0.001607" iyz="0.000256" izz="0.000399" />
      </inertial>
      <visual>
        <origin xyz="0 0 0" rpy="0 0 0" />
        <geometry>
          <mesh filename="package://kortex_description/arms/gen3/${dof}dof/meshes/spherical_wrist_1_link.STL" />
        </geometry>
        <material name="">
          <color rgba="0.75294 0.75294 0.75294 1" />
        </material>
      </visual>
      <collision>
        <origin xyz="0 0 0" rpy="0 0 0" />
        <geometry>
          <mesh filename="package://kortex_description/arms/gen3/${dof}dof/meshes/spherical_wrist_1_link.STL" />
        </geometry>
      </collision>
    </link>
    <joint
      name="${prefix}joint_5"
      type="continuous">
      <origin xyz="0 -0.20843 -0.006375" rpy="-1.5708 2.2204E-16 -6.373E-17" />
      <parent
        link="${prefix}forearm_link" />
      <child
        link="${prefix}spherical_wrist_1_link" />
      <axis
        xyz="0 0 1" />
      <limit
        effort="9"
        velocity="1.2218" />
    </joint>
    <link name="${prefix}spherical_wrist_2_link">
      <inertial>
        <origin xyz="1E-06 -0.045483 -0.00965" rpy="0 0 0" />
        <mass value="0.6781" />
        <inertia ixx="0.001641" ixy="0" ixz="0" iyy="0.00041" iyz="-0.000278" izz="0.001641" />
      </inertial>
      <visual>
        <origin xyz="0 0 0" rpy="0 0 0" />
        <geometry>
          <mesh filename="package://kortex_description/arms/gen3/${dof}dof/meshes/spherical_wrist_2_link.STL" />
        </geometry>
        <material name="">
          <color rgba="0.75294 0.75294 0.75294 1" />
        </material>
      </visual>
      <collision>
        <origin xyz="0 0 0" rpy="0 0 0" />
        <geometry>
          <mesh filename="package://kortex_description/arms/gen3/${dof}dof/meshes/spherical_wrist_2_link.STL" />
        </geometry>
      </collision>
    </link>
    <joint
      name="${prefix}joint_6"
      type="revolute">
      <origin xyz="0 0.00017505 -0.10593" rpy="1.5708 9.2076E-28 -8.2157E-15" />
      <parent
        link="${prefix}spherical_wrist_1_link" />
      <child
        link="${prefix}spherical_wrist_2_link" />
      <axis
        xyz="0 0 1" />
      <limit lower="-2.1" upper="2.1" effort="9" velocity="1.2218" />
    </joint>
    <xacro:if value="${vision}">
    <link name="${prefix}bracelet_link">
      <inertial>
        <origin xyz="0.000281 0.011402 -0.029798" rpy="0 0 0" />
        <mass value="0.5" />
        <inertia ixx="0.000587" ixy="3E-06" ixz="3E-06" iyy="0.000369" iyz="-0.000118" izz="0.000609" />
      </inertial>
      <visual>
        <origin xyz="0 0 0" rpy="0 0 0" />
        <geometry>
          <mesh filename="package://kortex_description/arms/gen3/${dof}dof/meshes/bracelet_with_vision_link.STL" />
        </geometry>
        <material name="">
          <color rgba="0.75294 0.75294 0.75294 1" />
        </material>
      </visual>
      <collision>
        <origin xyz="0 0 0" rpy="0 0 0" />
        <geometry>
          <mesh filename="package://kortex_description/arms/gen3/${dof}dof/meshes/bracelet_with_vision_link.STL" />
        </geometry>
      </collision>
    </link>
    </xacro:if>
    <xacro:unless value="${vision}">
    <link name="${prefix}bracelet_link">
      <inertial>
        <origin xyz="-9.3E-05 0.000132 -0.022905" rpy="0 0 0" />
        <mass value="0.364" />
        <inertia ixx="0.000214" ixy="0" ixz="1E-06" iyy="0.000223" iyz="-2E-06" izz="0.00024" />
      </inertial>
      <visual>
        <origin xyz="0 0 0" rpy="0 0 0" />
        <geometry>
          <mesh filename="package://kortex_description/arms/gen3/${dof}dof/meshes/bracelet_no_vision_link.STL" />
        </geometry>
        <material name="">
          <color rgba="0.75294 0.75294 0.75294 1" />
        </material>
      </visual>
      <collision>
        <origin xyz="0 0 0" rpy="0 0 0" />
        <geometry>
          <mesh filename="package://kortex_description/arms/gen3/${dof}dof/meshes/bracelet_no_vision_link.STL" />
        </geometry>
      </collision>
    </link>
    </xacro:unless>
    <joint
      name="${prefix}joint_7"
      type="continuous">
      <origin xyz="0 -0.10593 -0.00017505" rpy="-1.5708 -5.5511E-17 9.6396E-17" />
      <parent
        link="${prefix}spherical_wrist_2_link" />
      <child
        link="${prefix}bracelet_link" />
      <axis
        xyz="0 0 1" />
      <limit
        effort="9"
        velocity="1.2218" />
    </joint>
    <link name="${prefix}end_effector_link" />
    <joint
      name="${prefix}end_effector"
      type="fixed">
      <origin xyz="0 0 -0.0615250000000001" rpy="3.14159265358979 1.09937075168372E-32 0" />
      <parent
        link="${prefix}bracelet_link" />
      <child
        link="${prefix}end_effector_link" />
      <axis
        xyz="0 0 0" />
    </joint>
    <xacro:if value="${vision}">
      <!--link name="${prefix}camera_link" />
      <joint name="${prefix}camera_module" type="fixed">
        <origin xyz="0 0.05639 -0.00305" rpy="3.14159265358979 3.14159265358979 0" />
        <parent link="${prefix}end_effector_link" />
        <child  link="${prefix}camera_link" />
      </joint-->
      <link name="${prefix}camera_depth_frame" />
      <joint name="${prefix}depth_module" type="fixed">
        <!--origin xyz="0.0275 0.066 -0.00305" rpy="3.14159265358979 3.14159265358979 0" /-->
        <origin xyz="0.0275 0.066 0.00" rpy="3.14159265358979 3.14159265358979 1.5708" />
        <parent link="${prefix}end_effector_link" />
        <child  link="${prefix}camera_depth_frame" />
      </joint>
      <link name="${prefix}camera_color_frame" />
      <joint name="${prefix}color_module" type="fixed">
        <origin xyz="0 0.05639 0.00" rpy="3.14159265358979 3.14159265358979 1.5708" />
        <parent link="${prefix}end_effector_link" />
        <child  link="${prefix}camera_color_frame" />
      </joint>

      <link name="${prefix}imu_link" />
      <joint name="${prefix}imu_module" type="fixed">
        <origin xyz="0 0.05639 -0.00305" rpy="3.14159265358979 3.14159265358979 0" />
        <parent link="${prefix}end_effector_link" />
        <child  link="${prefix}imu_link" />
      </joint>



    <gazebo reference="${prefix}camera_color_frame">
      <sensor name="camera_rgb" type="camera">
        <!--pose degrees="true">0 0 0 0 0 -90</pose-->
        <!-- 20 cm between cameras: pose degrees="true">-0.15 0.0 0.0 0 0 -90</pose-->
	<!-- 10 cm between cameras -->
        <!--pose>-0.05 0.0 0.0 0 0 -90</pose-->
        <!--pose>0.032 -0.03 0.0 0 0 4.71</pose-->
        <!--pose>0.075 -0.03 0.0 0 0 4.71</pose-->
        <pose>0.0 0.0 0.0   0.0 -1.5708 0.0</pose>
        <visualize>true</visualize>
        <alwaysOn>true</alwaysOn>
        <update_rate>4</update_rate>
        <!--always_on>1</always_on-->
        <camera name="camera_rgb">
          <!-- zoom cameras horizontal_fov>0.8</horizontal_fov -->
          <!--pose>-0.25 0.0 0.0 0 0 0</pose-->
          <!--horizontal_fov>1.21126</horizontal_fov-->
          <horizontal_fov>1.0472</horizontal_fov> <!-- 1.0472 is 60 degrees -->
          <!--horizontal_fov>0.932</horizontal_fov--> <!-- camera is 60 degrees FOV diagonal, 16:9, thus 53.4 FOV horizontal -->
          <!--image_topic_name>image_raw</image_topic_name>
          <camera_info_topic>camera_info</camera_info_topic-->
          <image>
            <width>640</width>
            <height>480</height>
            <format>RGB_INT8</format>
          </image>
          <clip>
            <near>0.001</near>
            <far>25</far>
          </clip>
          <!--lens>
            <intrinsics>
              <fx>100</fx>
              <fy>100</fy>
              <cx>420</cx>
              <cy>240</cy>
              <s>0</s>
            </intrinsics>
          </lens-->
        </camera>
        <plugin name="camera_rgb_controller" filename="libgazebo_ros_camera.so">
            <alwaysOn>true</alwaysOn>
            <updateRate>4.0</updateRate>
            <cameraName>realsense/camera_rgb</cameraName>
            <imageTopicName>image_raw</imageTopicName>
            <cameraInfoTopicName>camera_info</cameraInfoTopicName>
            <frameName>${prefix}camera_color_frame</frameName>
            <!--frame_name>camera_link</frame_name>
                <always_on>true</always_on>
            <update_rate>0.0</update_rate>
            <camera_name>/realsense/camera_right</camera_name>
            <image_topic_name>image_raw</image_topic_name>
            <camera_info_topic_name>camera_info</camera_info_topic_name-->
            <hackBaseline>0.4</hackBaseline>
            <distortionK1>0.0</distortionK1>
            <distortionK2>0.0</distortionK2>
            <distortionK3>0.0</distortionK3>
            <distortionT1>0.0</distortionT1>
            <distortionT2>0.0</distortionT2>
        </plugin>
      </sensor>
    </gazebo>
      


    <gazebo reference="${prefix}camera_depth_frame">
      <sensor name="camera_depth" type="depth">
        <pose>0.0 -0.027 0.0   0.0 -1.5708 0.0</pose>
        <alwaysOn>true</alwaysOn>
        <visualize>false</visualize>
        <update_rate>4</update_rate>
        <!--always_on>1</always_on-->
        <camera name="camera_depth">
          <!-- zoom cameras horizontal_fov>0.8</horizontal_fov -->
          <!--pose>-0.25 0.0 0.0 0 0 0</pose-->
          <!--horizontal_fov>1.21126</horizontal_fov-->
          <!--horizontal_fov>1.0472</horizontal_fov-->
          <horizontal_fov>1.0472</horizontal_fov>
          <!--image_topic_name>image_raw</image_topic_name>
          <camera_info_topic>camera_info</camera_info_topic-->
          <image>
            <width>640</width>
            <height>480</height>
            <format>BGR_INT8</format>
          </image>
          <clip>
            <near>0.01</near>
            <far>25</far>
          </clip>
          <!--lens>
            <intrinsics>
              <fx>100</fx>
              <fy>100</fy>
              <cx>420</cx>
              <cy>240</cy>
              <s>0</s>
            </intrinsics>
          </lens-->
        </camera>
        <plugin name="camera_depth_controller" filename="libgazebo_ros_depth_camera.so">
        <!--plugin name="camera_depth_controller" filename="libgazebo_ros_openni_kinect.so"-->
            <alwaysOn>true</alwaysOn>
            <updateRate>4.0</updateRate>
            <cameraName>realsense/camera_depth</cameraName>
            <imageTopicName>depth_image_raw</imageTopicName>
            <cameraInfoTopicName>depth_image_info</cameraInfoTopicName>
            <depthImageTopicName>depth_raw</depthImageTopicName>
            <depthImageCameraInfoTopicName>depth_info</depthImageCameraInfoTopicName>
            <pointCloudTopicName>depth_points</pointCloudTopicName>
            <frameName>${prefix}camera_depth_frame</frameName>
            <pointCloudCutoff>0.01</pointCloudCutoff>
            <pointCloudCutoffMax>25.0</pointCloudCutoffMax>
            <min_depth>0.01</min_depth>
            <max_depth>25.0</max_depth>
            <!--frame_name>camera_link</frame_name>
                <always_on>true</always_on>
            <update_rate>0.0</update_rate>
            <camera_name>/realsense/camera_right</camera_name>
            <image_topic_name>image_raw</image_topic_name>
            <camera_info_topic_name>camera_info</camera_info_topic_name-->
            <hackBaseline>0.55</hackBaseline>
            <distortionK1>0.0</distortionK1>
            <distortionK2>0.0</distortionK2>
            <distortionK3>0.0</distortionK3>
            <distortionT1>0.0</distortionT1>
            <distortionT2>0.0</distortionT2>
        </plugin>
      </sensor>
    </gazebo>
      

    <gazebo reference="imu_link">
      <gravity>true</gravity>
      <sensor name="imu_sensor" type="imu">
        <pose>0.0 0.0 0.0   1.5708 -1.5708 0.0</pose>
        <visualize>false</visualize>
        <update_rate>8</update_rate>
        <always_on>1</always_on>
        <plugin name="imu_controller" filename="libgazebo_ros_imu_sensor.so">
            <topicName>imu</topicName>
            <bodyName>imu_link</bodyName>
            <alwaysOn>true</alwaysOn>
            <updateRateHZ>8</updateRateHZ>
            <frameName>imu_link</frameName>
            <gaussianNoise>0.0</gaussianNoise>
            <xyzOffset>0 0 0</xyzOffset>
            <rpyOffset>0 0 0</rpyOffset>
        </plugin>
      </sensor>
    </gazebo>
      
    </xacro:if>
  </xacro:macro>
</robot>
